<mujoco model="wam">
    <compiler angle="radian" meshdir="meshes" balanceinertia="true" autolimits="true"/>
    <option gravity="0 0 0" noslip_iterations="5"/> 

    <default>
        <light castshadow="false" diffuse="1 1 1" />
        <camera fovy="60" />
    </default>
    <default>
        <default class="viz">
            <geom type="mesh" contype="0" conaffinity="0" group="2" rgba="0.7 0.7 0.7 1" density="0"/>
        </default>
        <default class="col">
            <geom type="mesh" contype="0" conaffinity="1" group="3" rgba="0.5 0.6 0.7 1" density="0"/>
        </default>
        <default class="x_axis">
            <geom contype="0" conaffinity="0" group="1" rgba="1 0 0 1"
                  type="cylinder" size=".01 0.15" pos="0.15 0 0" euler="0 1.570796327 0"/>
        </default>
        <default class="y_axis">
            <geom contype="0" conaffinity="0" group="1" rgba="0 1 0 1"
                  type="cylinder" size=".01 0.15" pos="0 0.15 0" euler="1.570796327 0 0"/>
        </default>
        <default class="z_axis">
            <geom contype="0" conaffinity="0" group="1" rgba="0 0 1 1"
                  type="cylinder" size=".01 0.15" pos="0 0 0.15" euler="0 0 0"/>
        </default>
        <default class="x_s_axis">
            <geom contype="0" conaffinity="0" group="1" rgba="1 0 0 1"
                  type="cylinder" size=".005 0.05" pos="0.05 0 0" euler="0 1.570796327 0"/>
        </default>
        <default class="y_s_axis">
            <geom contype="0" conaffinity="0" group="1" rgba="0 1 0 1"
                  type="cylinder" size=".005 0.05" pos="0 0.05 0" euler="1.570796327 0 0"/>
        </default>
        <default class="z_s_axis">
            <geom contype="0" conaffinity="0" group="1" rgba="0 0 1 1"
                  type="cylinder" size=".005 0.05" pos="0 0 0.05" euler="0 0 0"/>
        </default>
        <default class="ur5e">
            <material specular="0.5" shininess="0.25"/>
            <joint axis="0 1 0" range="-6.28319 6.28319" armature="0.1"/>
            <general gaintype="fixed" biastype="affine" ctrlrange="-6.2831 6.2831" gainprm="2000" biasprm="0 -2000 -400"
                forcerange="-150 150"/>
            <default class="size3">
                <default class="size3_limited">
                <joint range="0 3.1415"/>
                <general ctrlrange="-3.1415 3.1415"/>
                </default>
            </default>
            <default class="size1">
                <general gainprm="500" biasprm="0 -500 -100" forcerange="-28 28"/>
            </default>
            <default class="visual">
                <geom type="mesh" contype="0" conaffinity="0" group="2"/>
            </default>
            <default class="collision">
                <geom type="capsule" group="3"/>
                <default class="eef_collision">
                <geom type="cylinder"/>
                </default>
            </default>
            <site size="0.001" rgba="0.5 0.5 0.5 0.3" group="4"/>
        </default>
        <default class="2f85">
            <mesh scale="0.001 0.001 0.001"/>
            <general biastype="affine"/>

            <joint axis="1 0 0"/>
            <default class="driver">
                <joint range="0 0.8" armature="0.005" damping="1" solimplimit="0.95 0.99 0.001" solreflimit="0.005 1"/>
            </default>
            <default class="follower">
                <joint range="-0.872664 0.872664" pos="0 -0.018 0.0065" solimplimit="0.95 0.99 0.001" solreflimit="0.005 1"/>
            </default>
            <default class="spring_link">
                <joint range="-0.29670597283 0.8" stiffness="0.8" springref="2.62" damping="0.00125"/>
            </default>
            <default class="coupler">
                <joint range="-1.57 0" solimplimit="0.95 0.99 0.001" solreflimit="0.005 1"/>
            </default>

            <default class="vis85">
                <geom type="mesh" contype="0" conaffinity="0" group="2"/>
            </default>
            <default class="col85">
                <geom type="mesh" group="3"/>
                <default class="pad_box1">
                <geom mass="0" type="box" pos="0 -0.0026 0.028125" size="0.011 0.004 0.009375" friction="0.7"
                    solimp="0.95 0.99 0.001" solref="0.004 1" priority="1" rgba="0.55 0.55 0.55 1"/>
                </default>
                <default class="pad_box2">
                <geom mass="0" type="box" pos="0 -0.0026 0.009375" size="0.011 0.004 0.009375" friction="0.6"
                    solimp="0.95 0.99 0.001" solref="0.004 1" priority="1" rgba="0.45 0.45 0.45 1"/>
                </default>
            </default>
        </default>

    </default>
    <custom>
        <numeric name="START_ANGLES" data="0.0 -2.0 0.0 3.14 0.0 -1.571 0.0" />
        <numeric name="URANGLE" data="1.571 -1.571 0.0 -1.571 0.0 0.0" />

<!--         <numeric name="START_ANGLES" data="-0.2055309491609746 1.1011781975966708 -0.7381169753691544 1.1783925365454948 -2.394643612318561 -1.1056478340717832 -1.753067389216457" />
        <numeric name="URANGLE" data="2.612507349380499 -1.9280790543891133 -1.2654139220556682 -1.51822612919953 1.571226799954258 1.7443435057680958" />
 -->        <numeric name="FINGER1" data="0 0 -0.838"/>
        <numeric name="FINGER2" data="0 0 -0.838"/>
        <numeric name="FINGER3" data="0 -0.838"/>
        <text name="google_id" data="1doam-DgkW7OSPnwWZQM84edzX84ot-GK" />
    </custom>

    <asset>
        <!-- UR5e models -->
        <mesh file="link0.stl"/>
        <mesh file="link1.stl"/>
        <mesh file="link1_cap.stl" />
        <mesh file="link1_connector.stl" />
        <mesh file="link2.stl" />
        <mesh file="link2_tube.stl" />
        <mesh file="link2_cap.stl" />
        <mesh file="link2_connector.stl" />
        <mesh file="link3a.stl" />
        <mesh file="link3a_connector.stl" />
        <mesh file="link3_tube.stl" />
        <mesh file="link3_cap.stl" />
        <mesh file="link3b.stl" />
        <mesh file="link3b_connector.stl" />
        <mesh file="link3b_connector2.stl"/>
        <mesh file="link4.stl" />
        <mesh file="link4_cap.stl" />
        <mesh file="link4_connector.stl" />
        <mesh file="link5.stl" />
        <mesh file="link5_cap.stl" />
        <mesh file="link5_connector.stl" />
        <mesh file="link6.stl" />
        <mesh file="link6_connector.stl" />


        <!-- WAM models -->
        <mesh file="base_link_fine.stl"/>
        <mesh file="base_link_convex.stl"/>
        <mesh file="shoulder_link_fine.stl"/>
        <mesh file="shoulder_link_convex_decomposition_p1.stl"/>
        <mesh file="shoulder_link_convex_decomposition_p2.stl"/>
        <mesh file="shoulder_link_convex_decomposition_p3.stl"/>
        <mesh file="shoulder_pitch_link_fine.stl"/>
        <mesh file="shoulder_pitch_link_convex.stl"/>
        <mesh file="upper_arm_link_fine.stl"/>
        <mesh file="upper_arm_link_convex_decomposition_p1.stl"/>
        <mesh file="upper_arm_link_convex_decomposition_p2.stl"/>
        <mesh file="elbow_link_fine.stl"/>
        <mesh file="elbow_link_convex.stl"/>
        <mesh file="forearm_link_fine.stl"/>
        <mesh file="forearm_link_convex_decomposition_p1.stl"/>
        <mesh file="forearm_link_convex_decomposition_p2.stl"/>
        <mesh file="wrist_yaw_link_fine.stl"/>
        <mesh file="wrist_yaw_link_convex_decomposition_p1.stl"/>
        <mesh file="wrist_yaw_link_convex_decomposition_p2.stl"/>
        <mesh file="wrist_pitch_link_fine.stl"/>
        <mesh file="wrist_pitch_link_convex_decomposition_p1.stl"/>
        <mesh file="wrist_pitch_link_convex_decomposition_p2.stl"/>
        <mesh file="wrist_pitch_link_convex_decomposition_p3.stl"/>
        <mesh file="wrist_palm_link_fine.stl"/>
        <mesh file="wrist_palm_link_convex.stl"/>
        <mesh file="Base_WAM.STL"/>
        <mesh file="New_Track.STL"/>
        <mesh file="satellite02.STL"/>

        <!--BHand Part-->
        <mesh file="bhand_palm_fine.stl"/>
		<mesh file="bhand_palm_link_convex_decomposition_p1.stl"/>
		<mesh file="bhand_palm_link_convex_decomposition_p2.stl"/>
		<mesh file="bhand_palm_link_convex_decomposition_p3.stl"/>
		<mesh file="bhand_palm_link_convex_decomposition_p4.stl"/>
		<mesh file="bhand_finger_prox_link_fine.stl"/>
		<mesh file="bhand_finger_prox_link_convex_decomposition_p1.stl"/>
		<mesh file="bhand_finger_prox_link_convex_decomposition_p2.stl"/>
		<mesh file="bhand_finger_prox_link_convex_decomposition_p3.stl"/>
		<mesh file="bhand_finger_med_link_fine.stl"/>
		<mesh file="bhand_finger_dist_link_fine.stl"/>
		<mesh file="bhand_finger_dist_link_convex.stl"/>
        <mesh file="zed.stl"/>
        <mesh file="zed_collision_mesh.stl"/>
        <mesh file="ZED_Base.stl"/>
        <mesh file="can.stl" name="can_mesh" scale="2.0 2.0 2.0" />

        <!--UR5e robot arm's gripper-->
        <mesh name="robotiq_85_base_link_coarse" file="robotiq_85_base_link_coarse.STL" />
        <mesh name="inner_knuckle_coarse" file="inner_knuckle_coarse.STL" />
        <mesh name="inner_finger_coarse" file="inner_finger_coarse.STL" />
        <mesh name="outer_knuckle_coarse" file="outer_knuckle_coarse.STL" />
        <mesh name="outer_finger_coarse" file="outer_finger_coarse.STL" />

    <mesh class="2f85" file="85_base_mount.stl"/>
    <mesh class="2f85" file="85_base.stl"/>
    <mesh class="2f85" file="85_driver.stl"/>
    <mesh class="2f85" file="85_coupler.stl"/>
    <mesh class="2f85" file="85_follower.stl"/>
    <mesh class="2f85" file="85_pad.stl"/>
    <mesh class="2f85" file="85_silicone_pad.stl"/>
    <mesh class="2f85" file="85_spring_link.stl"/>


    <material name="black" rgba="0.033 0.033 0.033 1"/>
    <material name="jointgray" rgba="0.278 0.278 0.278 1"/>
    <material name="linkgray" rgba="0.82 0.82 0.82 1"/>
    <material name="urblue" rgba="0.49 0.678 0.8 1"/>



    <mesh file="base_0.stl"/>
    <mesh file="base_1.stl"/>
    <mesh file="shoulder_0.stl"/>
    <mesh file="shoulder_1.stl"/>
    <mesh file="shoulder_2.stl"/>
    <mesh file="upperarm_0.stl"/>
    <mesh file="upperarm_1.stl"/>
    <mesh file="upperarm_2.stl"/>
    <mesh file="upperarm_3.stl"/>
    <mesh file="forearm_0.stl"/>
    <mesh file="forearm_1.stl"/>
    <mesh file="forearm_2.stl"/>
    <mesh file="forearm_3.stl"/>
    <mesh file="wrist1_0.stl"/>
    <mesh file="wrist1_1.stl"/>
    <mesh file="wrist1_2.stl"/>
    <mesh file="wrist2_0.stl"/>
    <mesh file="wrist2_1.stl"/>
    <mesh file="wrist2_2.stl"/>
    <mesh file="wrist3.stl"/>



        <mesh file="kinova_robotiq_coupler.stl" />
        <mesh file="robotiq_85_base_link.stl" />
        <mesh file="robotiq_85_finger_link.stl" />
        <mesh file="robotiq_85_finger_tip_link.stl" />
        <mesh file="robotiq_85_inner_knuckle_link.stl" />
        <mesh file="robotiq_85_knuckle_link.stl" />


        <!-- [OBJ] Hinge system -->
        <mesh file="base_link.STL" />
        <mesh file="hinge_link.STL" />
        <mesh file="stick_Link.STL" />
        <mesh file="panelAssembly5.STL" />
        <mesh file="newhinge.STL" />
        

        <texture name="floor_tile" type="2d" builtin="checker" rgb1=".2 .3 .4" rgb2=".1 0.15 0.2" width="512" height="512" mark="cross" markrgb=".8 .8 .8"/>
        <material name="tile" texture="floor_tile" specular="0" shininess="0" reflectance="0" emission="1" />

        <texture name="foam_blocks" file="meshes/foam_blocks.png" width="2744" height="2744" type="2d"/>
        <material name="foam" texture="foam_blocks" specular="0" shininess="0" reflectance="0" emission="1" />
        <material name="matplane" reflectance="0.3" texture="floor_tile" texrepeat="1 1" texuniform="true"/>
        <material name="silver" specular="1" shininess="0.5" reflectance="1" emission="0.25" rgba="0.82 0.82 0.82 1"/>
        <material name="grey" specular="1" shininess="0.5" reflectance="1" emission="0.1" rgba="0.5 0.5 0.5 1"/>
        <material name="gray" rgba="0.4627 0.4627 0.4627 1"/>
        <material name="silicone" rgba="0.1882 0.1882 0.1882 1"/>

        <material name="blue" specular="1" shininess="0.5" reflectance="1" emission="0" rgba="0.678 0.847 0.902 1"/>
        <!--<material name="black" specular="1" shininess="0.5" reflectance="1" emission="0" rgba="0.2 0.2 0.2 1"/>-->
        <material name="RobMat" specular="0.9" shininess="0.5" reflectance="0" rgba="0.7 0.7 0.7 1" emission="0.1" />
        <material name="GriMat" specular="0.9" shininess="0.5" reflectance="0" rgba="0.1 0.1 0.1 1" emission="0.1" />
        <material name="Light" specular="0" shininess="0.6" reflectance="0.9" rgba="0.5 0.5 1 1" emission="0.7" />
        <material name="BasketMat" specular="0" shininess="0" reflectance="0" rgba="0.26 0.16 0.16796875 1" emission="0" />
        <texture file="meshes/wood.png" name="hinge-wood"/>
        <material name="wood" reflectance="0.7" texrepeat="5 5" texture="hinge-wood" texuniform="true"/>
    </asset>

    <worldbody>
       
        <geom name="floor_grey_tile" pos="0 0 -0.75" size="5 2 .25" type="plane" material="matplane" condim="3" solref="-16000 -200"/>

        <!-- Table - for hinge -->
        <geom name="workbench_down1" pos="0.5 -0.22 -0.7" size="0.1 0.1 0.7" type="box" rgba="1 1 1 1" material="wood" condim="4"/>
  
        <!-- Table - for satellite -->
        <geom name="workbench_down2" pos="0.6 0.22 -0.7" size="0.1 0.1 0.7" type="box" rgba="1 1 1 1" material="wood" condim="4"/>

        <!-- control visualizations -->
        <body name="hand" pos="0 0 -0.15" mocap="true">
            <geom type="box" size=".002 .004 .006" rgba="0.9 0 0 .5" contype="2" conaffinity="2"/>
        </body>

        <body name="hand_ur" pos="0 0 -0.25" mocap="true">
            <geom type="box" size=".002 .004 .006" rgba="0 .9 0 .5" contype="2" conaffinity="2"/>
        </body>

        <body name="target" pos="0 0 -0.15" mocap="true">
            <geom name="target" type="sphere" size="0.05" rgba=".9 0 0 .0" contype="4" conaffinity="4"/>
        </body>

        <body name="target_orientation" pos="0 0 -0.15" mocap="true">
            <geom name="target_or" type="box" size=".04 .06 .02" rgba=".9 0 0 .0" contype="32" conaffinity="32"/>
        </body>

        <body name="ur_target_orientation" pos="0 0 -0.15" mocap="true">
            <geom name="ur_target_or" type="box" size=".04 .06 .02" rgba=".9 0 0 .0" contype="32" conaffinity="32"/>
        </body>

        <body name="path_planner" pos="0 0 -0.15" mocap="true">
            <geom type="sphere" size="0.05" rgba="0 1 1 0.5" contype="16" conaffinity="16"/>
        </body>

        <body name="path_planner_orientation" pos="0 0 -0.15" mocap="true">
            <geom type="box" size=".02 .04 .06" rgba="0 1 1 .5" contype="32" conaffinity="32"/>
        </body>

        <body name="pivot_ref" pos="0.535 -0.202 0.026" mocap="true">
            <geom type="box" size=".001 .001 0.1" rgba="0 0 1 1" contype="8" conaffinity="8"/>
        </body>

        <!--Only for test
        <body name="pivot_axis" pos="0.03491212 0.79747317 -0.0198">
            <geom name="pivotaxissee" type="cylinder" size=".002 0.4" rgba=".9 0.9 0 .5" contype="8" conaffinity="8"/>
        </body>-->

        <light directional="true" pos="-0.5 0.5 3" dir="0 0 -1" />
        <!--This plate is for WAM-->
        <body name="wam/links/base_plate" pos="-9.72 -0.70 -0.41">
            <inertial pos="-0.08071720 0.01017671 0.07995294" mass="9.97059584" diaginertia="0.11760385 0.10916849 0.18294303" /> 
            <geom type="mesh" mesh="Base_WAM" rgba="0.2 0.2 0.2 1"/>
            <geom type="mesh" mesh="Base_WAM" rgba="0.2 0.2 0.2 1"/>
        </body>

        <!--This plate is for UR5e-->
        <body name="ur5/links/base_plate" pos="11.02 0.70 -0.41" quat="0 0 0 1">
            <inertial pos="-0.08071720 0.01017671 0.07995294" mass="9.97059584" diaginertia="0.11760385 0.10916849 0.18294303" /> 
            <geom type="mesh" mesh="Base_WAM" rgba="0.2 0.2 0.2 1"/>
            <geom type="mesh" mesh="Base_WAM" rgba="0.2 0.2 0.2 1"/> 
            <body name="car_ur5" pos="9.72 0.70 0.41" quat="0 0 0 1">
                <geom class="x_axis"/>
                <geom class="y_axis"/>
                <geom class="z_axis"/>
            </body>
        </body>

        <!-- Track system for Arm -->
        <body name="wam/links/Track" pos="-1.5 0.19 -0.75" quat="0.707107 0.707107 0 0">
            <inertial pos="1.5 0.3 0.2" mass="10.2" diaginertia="0.0521107 4.907043 4.884550" /> 
            <geom type="mesh" mesh="New_Track" material="BasketMat"/>
            <geom type="mesh" mesh="New_Track" conaffinity="1" material="BasketMat"/>
        </body>
        <!-- Pure satellite model -->
        <body pos="0.5 0.32 0" name="satellite" mocap="true" euler="1.57 0 0">
            <geom type="mesh" rgba="0.1 0.7 0.7 1" mesh="satellite02" mass="2"/>

<!--             <body name="handle_1" pos="0.1 0.08 0" euler="0 0 1.57">
                <geom name="handle_1" type="box" size="0.01 0.05 0.08" rgba="1.0 0.0 0.0 1" mass="2"/>
            </body>

            <body name="handle_2" pos="0.1 0.08 0.2" euler="0 0 1.57">
                <geom name="handle_2" type="box" size="0.01 0.05 0.08" rgba="0.0 1 0.0 1" mass="2"/>
            </body> -->
            
        </body>
        

        <body name="wam/links/base" pos="0 0 0">
            <inertial pos="-0.08071720 0.01017671 0.07995294" mass="9.97059584" diaginertia="0.11760385 0.10916849 0.18294303" /> 
            <site name="wam/mass_sites/base" pos="-0.08071720 0.01017671 0.07995294"/>
            <geom class="x_axis"/>
            <geom class="y_axis"/>
            <geom class="z_axis"/>
            <geom class="viz" mesh="base_link_fine" />
            <geom class="col" mesh="base_link_convex"/>
            
            <body name="wam/links/shoulder_yaw" pos="0 0 0.346" >
                <inertial pos="-0.00443422 -0.00066489 -0.12189039  " mass="10.76768767" diaginertia="0.13488033 0.09046330 0.11328369" />
                <site name="wam/mass_sites/shoulder_yaw" pos="-0.00443422 -0.00066489 -0.12189039"/>
                <joint name="wam/joints/base_yaw" range="-2.6 2.6" armature="0.1" damping="100" limited="true"/> <!--armature="1.2" damping="0.2"-->
                <geom class="viz" mesh="shoulder_link_fine" condim="4"/>
                <geom class="col" mesh="shoulder_link_convex_decomposition_p1" condim="4"/>
                <geom class="col" mesh="shoulder_link_convex_decomposition_p2" condim="4"/>
                <geom class="col" mesh="shoulder_link_convex_decomposition_p3" condim="4"/>
                <body name="wam/links/shoulder_pitch" pos="0 0 0" quat="0.707107 -0.707107 0 0">

                    <inertial pos="-0.00236983 -0.01542114 0.0" mass="3.87493756" diaginertia="0.02140958 0.01558906 0.01377875" />
                    <site name="wam/mass_sites/shoulder_pitch" pos="-0.00236983 -0.01542114 0.03105614"/>
                    <joint name="wam/joints/shoulder_pitch_joint" range="-2.0 2.0" armature="0.1" damping="0.2" limited="true"/>
                    <geom class="viz" mesh="shoulder_pitch_link_fine" condim="4"/>
                    <geom class="col" mesh="shoulder_pitch_link_convex" condim="4"/>

                    <body name="wam/links/upper_arm" pos="0 -0.505 0" quat="0.707107 0.707107 0 0">
                        <inertial pos="0.00674142 -0.00003309 -0.1724923" mass="1.80228141" diaginertia="0.05911077 0.05927043 0.00324550" />
                        <site name="wam/mass_sites/upper_arm" pos="-0.03825858 0.00003309 -0.20750770"/>
                        <joint name="wam/joints/shoulder_yaw" range="-2.8 2.8" armature="1.2" damping="0.2" limited="true"/>
                        <geom class="viz" mesh="upper_arm_link_fine" pos="0 0 -0.505" condim="4"/>
                        <geom class="col" mesh="upper_arm_link_convex_decomposition_p1" pos="0 0 -0.505" condim="4"/>
                        <geom class="col" mesh="upper_arm_link_convex_decomposition_p2" pos="0 0 -0.505" condim="4"/>

                        <body name="wam/links/forearm" pos="0.045 0 0.045" quat="0.707107 -0.707107 0 0">
                            <inertial pos="-0.04498512 -0.14871662 -0.00022942" mass="2.40016804" diaginertia="0.01491672 0.00294463 0.01482922" />
                            <site name="wam/mass_sites/forearm" pos="0.00498512 -0.13271662 -0.00022942"/>
                            <joint name="wam/joints/elbow_pitch" range="-0.9 3.14159" armature="1.2" damping="0.2" limited="true"/>
                            <geom class="viz" mesh="elbow_link_fine" condim="4"/>
                            <geom class="col" mesh="elbow_link_convex" condim="4"/>
                            <geom class="viz" mesh="forearm_link_fine" pos="-.045 -0.0730 0" euler="1.57 0 0" condim="4"/>
                            <geom class="col" mesh="forearm_link_convex_decomposition_p1" pos="-0.045 -0.0730 0" euler="1.57 0 0" condim="4"/>
                            <geom class="col" mesh="forearm_link_convex_decomposition_p2" pos="-.045 -0.0730 0" euler="1.57 0 0" condim="4"/>
                            <body name="wam/links/wrist_yaw" pos="-0.045 0.0 0.0" quat="0.707107 0.707107 0 0">
                                <inertial pos="0.00008921 0.00511217 0.3" mass="0.12376019" diaginertia="0.00005029 0.00006270 0.00007582" />
                                <site name="wam/mass_sites/wrist_yaw" pos="0.00008921 0.00435824 -0.00511217"/>
                                <joint name="wam/joints/wrist_yaw" range="-4.8 1.3" armature="1.2" damping="0.2" limited="true"/>
                                <geom class="viz" mesh="wrist_yaw_link_fine" pos="0 0 0.3" condim="4"/>
                                <geom class="col" mesh="wrist_yaw_link_convex_decomposition_p1" pos="0 0 0.3" condim="4"/>
                                <geom class="col" mesh="wrist_yaw_link_convex_decomposition_p2" pos="0 0 0.3" condim="4"/>

                                <body name="wam/links/wrist_pitch" pos="0 0 0.3" quat="0.707107 -0.707107 0 0">
                                    <inertial pos="-0.00012262 -0.02468336 -0.00703194" mass="0.41797364" diaginertia="0.00055516 0.00045358 0.00024367" />
                                    <site name="wam/mass_sites/wrist_pitch" pos="-0.00012262 -0.02468336 -0.01703194"/>
                                    <joint name="wam/joints/wrist_pitch" range="-1.6 1.6" armature="1.2" damping="0.2" limited="true"/>
                                    <geom class="viz" mesh="wrist_pitch_link_fine" pos="0 0 0" condim="4"/>
                                    <geom class="col" mesh="wrist_pitch_link_convex_decomposition_p1" condim="4"/>
                                    <geom class="col" mesh="wrist_pitch_link_convex_decomposition_p2" condim="4"/>
                                    <geom class="col" mesh="wrist_pitch_link_convex_decomposition_p3" condim="4"/>

                                    <body name="wam/links/wrist_palm" pos="0 -0.06 0" quat="0.707107 0.707107 0 0">
                                        <inertial pos="-0.00007974 -0.00323552 -0.00016313" mass="0.06864753" diaginertia="0.00003773 0.00003806 0.00007408" />
                                        <site name="wam/mass_sites/wrist_palm" pos="-0.00007974 -0.00323552 -0.00016313"/>
                                        <joint name="wam/joints/palm_yaw" range="-3 3" armature="1.2" damping="0.2" limited="true"/>
                                        <geom class="viz" mesh="wrist_palm_link_fine" pos="0 0 -0.06"/>
                                        <geom class="x_s_axis"/>
                                        <geom class="y_s_axis"/>
                                        <geom class="z_s_axis"/>
                                        <site name="wrist_WAM_torque_7" pos="0 0 0" size="0.05 0.01" type="cylinder" rgba="0 0 0.8 0.2" euler="0 0 0"/>
                                        <site name="wrist_WAM_force_7" pos="0 0 0" size="0.05 0.01" type="cylinder" rgba="0 0 0.8 0.2" euler="0 0 0"/>
                                                                                    <!-- for palm EE -->
                                        <body name="EE" pos="0 0 0.12" euler="0 0 0">
                                            <site name="speed_sensor" pos="0 0 0" rgba="1 0 0 0" size="0.01 0.01 0.01" type="box"/>
                                        </body>    
                                        
                                            <body name="wam/bhand/bhand_palm_link" pos="0 0 0.0" quat="0.707 0 0 0.707">
                                                <inertial pos="-5.1098e-005 0.0050433 0.036671" quat="0.553098 0.439047 0.434456 0.559078" mass="0.50573" diaginertia="0.000224052 0.000210701 2.81212e-005" />
                                                <site name="wam/mass_sites/bhand_palm_link" pos="-0.00007974 -0.00323552 -0.00016313"/>
                                                <!--<geom class="x_s_axis" pos="-0.05 0 0.08"/>
                                                <geom class="y_s_axis" pos="0 -0.05 0.08"/>
                                                <geom class="z_s_axis" pos="0 0 0.13"/>-->
                                                <geom name="bhand_palm_link" class="viz" mesh="bhand_palm_fine"/>
                                                <geom class="col" mesh="bhand_palm_fine" material="RobMat"/>
                                                <body name="wam/bhand/finger_3/med_link" pos="0 0.05 0.0754" quat="0.5 0.5 0.5 0.5">
                                                    <inertial pos="0.023133 0.00078642 0.00052792" quat="0.0160796 0.707269 -0.000766008 0.706762" mass="0.062139" diaginertia="7.77335e-005 7.66282e-005 4.83122e-006" />
                                                    <site name="wam/mass_sites/finger_3/med_link" pos="0.023133 0.00078642 0.00052792"/>
                                                    <joint name="wam/bhand/finger_3/med_joint" range="-2.44346 2.44346" damping="0.11" limited="true"/>
                                                    <geom class="viz" mesh="bhand_finger_med_link_fine"/>
                                                    <geom class="col" mesh="bhand_finger_med_link_fine" material="RobMat"/>
                                                    <body name="wam/bhand/finger_3/dist_link" pos="0.06994 0.003 0" quat="0.92388 0 0 0.382683">
                                                        <inertial pos="0.022825 0.0010491 0.0004203" quat="0.508412 0.51165 0.489583 0.489939" mass="0.041377" diaginertia="3.8434e-005 3.72753e-005 3.09987e-006" />
                                                        <site name="wam/mass_sites/finger_3/dist_link" pos="0.022825 0.0010491 0.0004203"/>
                                                        <joint name="wam/bhand/finger_3/dist_joint" range="-0.837758 0.837758" damping="0.11" limited="true"/>
                                                        <geom class="viz" mesh="bhand_finger_dist_link_fine" euler="0 0 -.84"/>
                                                        <geom class="col" mesh="bhand_finger_dist_link_fine" euler="0 0 -.84" material="RobMat"/>
                                                            <site name="sensorsurf3_0_1" pos="0.024 0.0060 0.006" size=".002 .002 .003" type="box" rgba="0.3 0.2 0.1 0.3" euler="0 0 -0.10"/>
                                                            <site name="sensorsurf3_0_2" pos="0.024 0.0060 0.000" size=".002 .002 .003" type="box" rgba="0.3 0.2 0.1 0.3" euler="0 0 -0.10"/>
                                                            <site name="sensorsurf3_0_3" pos="0.024 0.0060 -0.006" size=".002 .002 .003" type="box" rgba="0.3 0.2 0.1 0.3" euler="0 0 -0.10"/>  
                                                            <site name="sensorsurf3_1_1" pos="0.028 0.0053 0.006" size=".002 .002 .003" type="box" rgba="0.3 0.2 0.1 0.3" euler="0 0 -0.10"/>
                                                            <site name="sensorsurf3_1_2" pos="0.028 0.0053 0.000" size=".002 .002 .003" type="box" rgba="0.3 0.2 0.1 0.3" euler="0 0 -0.10"/>
                                                            <site name="sensorsurf3_1_3" pos="0.028 0.0053 -0.006" size=".002 .002 .003" type="box" rgba="0.3 0.2 0.1 0.3" euler="0 0 -0.10"/>  
                                                            <site name="sensorsurf3_2_1" pos="0.032 0.0047 0.006" size=".002 .002 .003" type="box" rgba="0.3 0.2 0.1 0.3" euler="0 0 -0.10"/>
                                                            <site name="sensorsurf3_2_2" pos="0.032 0.0047 0.000" size=".002 .002 .003" type="box" rgba="0.3 0.2 0.1 0.3" euler="0 0 -0.10"/>
                                                            <site name="sensorsurf3_2_3" pos="0.032 0.0047 -0.006" size=".002 .002 .003" type="box" rgba="0.3 0.2 0.1 0.3" euler="0 0 -0.10"/>  
                                                            <site name="sensorsurf3_3_1" pos="0.036 0.004 0.006" size=".002 .002 .003" type="box" rgba="0.3 0.2 0.1 0.3" euler="0 0 -0.20"/>
                                                            <site name="sensorsurf3_3_2" pos="0.036 0.004 0.000" size=".002 .002 .003" type="box" rgba="0.3 0.2 0.1 0.3" euler="0 0 -0.20"/>
                                                            <site name="sensorsurf3_3_3" pos="0.036 0.004 -0.006" size=".002 .002 .003" type="box" rgba="0.3 0.2 0.1 0.3" euler="0 0 -0.20"/>                                                            
                                                            <site name="sensorsurf3_4_1" pos="0.04 0.0035 0.006" size=".002 .002 .003" type="box" rgba="0.3 0.2 0.1 0.3" euler="0 0 -0.20"/>
                                                            <site name="sensorsurf3_4_2" pos="0.04 0.0035 0.000" size=".002 .002 .003" type="box" rgba="0.3 0.2 0.1 0.3" euler="0 0 -0.20"/>
                                                            <site name="sensorsurf3_4_3" pos="0.04 0.0035 -0.006" size=".002 .002 .003" type="box" rgba="0.3 0.2 0.1 0.3" euler="0 0 -0.20"/>
                                                            <site name="sensorsurf3_5_1" pos="0.044 0.0026 0.006" size=".002 .002 .003" type="box" rgba="0.3 0.2 0.1 0.3" euler="0 0 -0.20"/>
                                                            <site name="sensorsurf3_5_2" pos="0.044 0.0026 0.000" size=".002 .002 .003" type="box" rgba="0.3 0.2 0.1 0.3" euler="0 0 -0.20"/>
                                                            <site name="sensorsurf3_5_3" pos="0.044 0.0026 -0.006" size=".002 .002 .003" type="box" rgba="0.3 0.2 0.1 0.3" euler="0 0 -0.20"/>
                                                            <site name="sensorsurf3_6_1" pos="0.048 0.0018 0.006" size=".002 .002 .003" type="box" rgba="0.3 0.2 0.1 0.3" euler="0 0 -0.20"/>
                                                            <site name="sensorsurf3_6_2" pos="0.048 0.0018 0.000" size=".002 .002 .003" type="box" rgba="0.3 0.2 0.1 0.3" euler="0 0 -0.20"/>
                                                            <site name="sensorsurf3_6_3" pos="0.048 0.0018 -0.006" size=".002 .002 .003" type="box" rgba="0.3 0.2 0.1 0.3" euler="0 0 -0.20"/>
                                                            <site name="sensorsurf3_7_1" pos="0.052 0.0000 0.006" size=".002 .002 .003" type="box" rgba="0.3 0.2 0.1 0.3" euler="0 0 -0.20"/>
                                                            <site name="sensorsurf3_7_2" pos="0.052 0.0000 0.000" size=".002 .002 .003" type="box" rgba="0.3 0.2 0.1 0.3" euler="0 0 -0.20"/>
                                                            <site name="sensorsurf3_7_3" pos="0.052 0.0000 -0.006" size=".002 .002 .003" type="box" rgba="0.3 0.2 0.1 0.3" euler="0 0 -0.20"/>
                                                    </body>
                                                </body>
                                                <body name="wam/bhand/finger_1/prox_link" pos="-0.025 0 0.0415" quat="0.707107 0 0 -0.707107">
                                                    <inertial pos="0.023133 0.00078642 0.00052792" quat="0.0160796 0.707269 -0.000766008 0.706762" mass="0.14109" diaginertia="7.77335e-005 7.66282e-005 4.83122e-006" />
                                                    <site name="wam/mass_sites/finger_1/prox_link" pos="-0.025 0 0.0415"/>
                                                    <joint name="wam/bhand/finger_1/prox_joint" axis="0 0 -1" range="0 3.14159" damping="0.11" limited="true"/>
                                                    <geom class="viz" mesh="bhand_finger_prox_link_fine"/>
                                                    <body name="wam/bhand/finger_1/med_link" pos="0.05 0 0.0339" quat="0.707107 0.707107 0 0">
                                                        <inertial pos="0.023133 0.00078642 0.00052792" quat="0.0160796 0.707269 -0.000766008 0.706762" mass="0.062139" diaginertia="7.77335e-005 7.66282e-005 4.83122e-006" />
                                                        <site name="wam/mass_sites/finger_1/med_link" pos="0.05 0 0.0339"/>
                                                        <joint name="wam/bhand/finger_1/med_joint" range="-2.44346 2.44346" damping="0.11" limited="true"/>
                                                        <geom class="viz" mesh="bhand_finger_med_link_fine"/>
                                                        <geom class="col" mesh="bhand_finger_prox_link_fine" material="RobMat"/>
                                                        <body name="wam/bhand/finger_1/dist_link" pos="0.06994 0.003 0" quat="0.92388 0 0 0.382683">
                                                            <inertial pos="0.022825 0.0010491 0.0004203" quat="0.508412 0.51165 0.489583 0.489939" mass="0.041377" diaginertia="3.8434e-005 3.72753e-005 3.09987e-006" />
                                                            <site name="wam/mass_sites/finger_1/dist_link" pos="0.06994 0.003 0"/>
                                                            <joint name="wam/bhand/finger_1/dist_joint" range="-0.837758 0.837758" damping="0.11" limited="true"/>
                                                            <geom class="viz" mesh="bhand_finger_dist_link_fine" euler="0 0 -.84"/>  
                                                            <geom class="col" mesh="bhand_finger_dist_link_fine" euler="0 0 -.84" material="RobMat"/>
                                                            <site name="sensorsurf1_0_1" pos="0.024 0.0060 0.006" size=".002 .002 .003" type="box" rgba="0.3 0.2 0.1 0.3" euler="0 0 -0.10"/>
                                                            <site name="sensorsurf1_0_2" pos="0.024 0.0060 0.000" size=".002 .002 .003" type="box" rgba="0.3 0.2 0.1 0.3" euler="0 0 -0.10"/>
                                                            <site name="sensorsurf1_0_3" pos="0.024 0.0060 -0.006" size=".002 .002 .003" type="box" rgba="0.3 0.2 0.1 0.3" euler="0 0 -0.10"/>  
                                                            <site name="sensorsurf1_1_1" pos="0.028 0.0053 0.006" size=".002 .002 .003" type="box" rgba="0.3 0.2 0.1 0.3" euler="0 0 -0.10"/>
                                                            <site name="sensorsurf1_1_2" pos="0.028 0.0053 0.000" size=".002 .002 .003" type="box" rgba="0.3 0.2 0.1 0.3" euler="0 0 -0.10"/>
                                                            <site name="sensorsurf1_1_3" pos="0.028 0.0053 -0.006" size=".002 .002 .003" type="box" rgba="0.3 0.2 0.1 0.3" euler="0 0 -0.10"/>  
                                                            <site name="sensorsurf1_2_1" pos="0.032 0.0047 0.006" size=".002 .002 .003" type="box" rgba="0.3 0.2 0.1 0.3" euler="0 0 -0.10"/>
                                                            <site name="sensorsurf1_2_2" pos="0.032 0.0047 0.000" size=".002 .002 .003" type="box" rgba="0.3 0.2 0.1 0.3" euler="0 0 -0.10"/>
                                                            <site name="sensorsurf1_2_3" pos="0.032 0.0047 -0.006" size=".002 .002 .003" type="box" rgba="0.3 0.2 0.1 0.3" euler="0 0 -0.10"/>  
                                                            <site name="sensorsurf1_3_1" pos="0.036 0.004 0.006" size=".002 .002 .003" type="box" rgba="0.3 0.2 0.1 0.3" euler="0 0 -0.20"/>
                                                            <site name="sensorsurf1_3_2" pos="0.036 0.004 0.000" size=".002 .002 .003" type="box" rgba="0.3 0.2 0.1 0.3" euler="0 0 -0.20"/>
                                                            <site name="sensorsurf1_3_3" pos="0.036 0.004 -0.006" size=".002 .002 .003" type="box" rgba="0.3 0.2 0.1 0.3" euler="0 0 -0.20"/>                                                            
                                                            <site name="sensorsurf1_4_1" pos="0.04 0.0035 0.006" size=".002 .002 .003" type="box" rgba="0.3 0.2 0.1 0.3" euler="0 0 -0.20"/>
                                                            <site name="sensorsurf1_4_2" pos="0.04 0.0035 0.000" size=".002 .002 .003" type="box" rgba="0.3 0.2 0.1 0.3" euler="0 0 -0.20"/>
                                                            <site name="sensorsurf1_4_3" pos="0.04 0.0035 -0.006" size=".002 .002 .003" type="box" rgba="0.3 0.2 0.1 0.3" euler="0 0 -0.20"/>
                                                            <site name="sensorsurf1_5_1" pos="0.044 0.0026 0.006" size=".002 .002 .003" type="box" rgba="0.3 0.2 0.1 0.3" euler="0 0 -0.20"/>
                                                            <site name="sensorsurf1_5_2" pos="0.044 0.0026 0.000" size=".002 .002 .003" type="box" rgba="0.3 0.2 0.1 0.3" euler="0 0 -0.20"/>
                                                            <site name="sensorsurf1_5_3" pos="0.044 0.0026 -0.006" size=".002 .002 .003" type="box" rgba="0.3 0.2 0.1 0.3" euler="0 0 -0.20"/>
                                                            <site name="sensorsurf1_6_1" pos="0.048 0.0018 0.006" size=".002 .002 .003" type="box" rgba="0.3 0.2 0.1 0.3" euler="0 0 -0.20"/>
                                                            <site name="sensorsurf1_6_2" pos="0.048 0.0018 0.000" size=".002 .002 .003" type="box" rgba="0.3 0.2 0.1 0.3" euler="0 0 -0.20"/>
                                                            <site name="sensorsurf1_6_3" pos="0.048 0.0018 -0.006" size=".002 .002 .003" type="box" rgba="0.3 0.2 0.1 0.3" euler="0 0 -0.20"/>
                                                            <site name="sensorsurf1_7_1" pos="0.052 0.0000 0.006" size=".002 .002 .003" type="box" rgba="0.3 0.2 0.1 0.3" euler="0 0 -0.20"/>
                                                            <site name="sensorsurf1_7_2" pos="0.052 0.0000 0.000" size=".002 .002 .003" type="box" rgba="0.3 0.2 0.1 0.3" euler="0 0 -0.20"/>
                                                            <site name="sensorsurf1_7_3" pos="0.052 0.0000 -0.006" size=".002 .002 .003" type="box" rgba="0.3 0.2 0.1 0.3" euler="0 0 -0.20"/>
                                                        </body>
                                                    </body>
                                                </body>
                                                <body name="wam/bhand/finger_2/prox_link" pos="0.025 0 0.0415" quat="0.707107 0 0 -0.707107">
                                                    <inertial pos="0.023133 0.00078642 0.00052792" quat="0.0160796 0.707269 -0.000766008 0.706762" mass="0.14109" diaginertia="7.77335e-005 7.66282e-005 4.83122e-006" />
                                                    <site name="wam/mass_sites/finger_2/prox_link" pos="0.025 0 0.0415"/>
                                                    <joint name="wam/bhand/finger_2/prox_joint" range="0 3.14159" damping="0.11" limited="true"/>
                                                    <geom class="viz" mesh="bhand_finger_prox_link_fine"/>
                                                    <geom class="col" mesh="bhand_finger_prox_link_fine"/>
                                                    <body name="wam/bhand/finger_2/med_link" pos="0.05 0 0.0339" quat="0.707107 0.707107 0 0">
                                                        <inertial pos="0.023133 0.00078642 0.00052792" quat="0.0160796 0.707269 -0.000766008 0.706762" mass="0.062139" diaginertia="7.77335e-005 7.66282e-005 4.83122e-006" />
                                                        <site name="wam/mass_sites/finger_2/med_link" pos="0.05 0 0.0339"/>
                                                        <joint name="wam/bhand/finger_2/med_joint" range="-2.44346 2.44346" damping="0.11" limited="true"/>
                                                        <geom class="viz" mesh="bhand_finger_med_link_fine"/>
                                                        <geom class="col" mesh="bhand_finger_med_link_fine" material="RobMat"/>                                                
                                                        <body name="wam/bhand/finger_2/dist_link" pos="0.06994 0.003 0" quat="0.92388 0 0 0.382683">
                                                            <inertial pos="0.022825 0.0010491 0.0004203" quat="0.508412 0.51165 0.489583 0.489939" mass="0.041377" diaginertia="3.8434e-005 3.72753e-005 3.09987e-006" />
                                                            <site name="wam/mass_sites/finger_2/dist_link" pos="0.06994 0.003 0"/>
                                                            <joint name="wam/bhand/finger_2/dist_joint" range="-0.837758 0.837758" damping="0.11" limited="true"/>
                                                            <geom class="viz" mesh="bhand_finger_dist_link_fine" euler="0 0 -.84"/>
                                                            <geom class="col" mesh="bhand_finger_dist_link_fine" euler="0 0 -.84" material="RobMat"/>
                                                            
                                                            <site name="sensorsurf2_0_1" pos="0.024 0.0060 0.006" size=".002 .002 .003" type="box" rgba="0.3 0.2 0.1 0.3" euler="0 0 -0.10"/>
                                                            <site name="sensorsurf2_0_2" pos="0.024 0.0060 0.000" size=".002 .002 .003" type="box" rgba="0.3 0.2 0.1 0.3" euler="0 0 -0.10"/>
                                                            <site name="sensorsurf2_0_3" pos="0.024 0.0060 -0.006" size=".002 .002 .003" type="box" rgba="0.3 0.2 0.1 0.3" euler="0 0 -0.10"/>  
                                                            <site name="sensorsurf2_1_1" pos="0.028 0.0053 0.006" size=".002 .002 .003" type="box" rgba="0.3 0.2 0.1 0.3" euler="0 0 -0.10"/>
                                                            <site name="sensorsurf2_1_2" pos="0.028 0.0053 0.000" size=".002 .002 .003" type="box" rgba="0.3 0.2 0.1 0.3" euler="0 0 -0.10"/>
                                                            <site name="sensorsurf2_1_3" pos="0.028 0.0053 -0.006" size=".002 .002 .003" type="box" rgba="0.3 0.2 0.1 0.3" euler="0 0 -0.10"/>  
                                                            <site name="sensorsurf2_2_1" pos="0.032 0.0047 0.006" size=".002 .002 .003" type="box" rgba="0.3 0.2 0.1 0.3" euler="0 0 -0.10"/>
                                                            <site name="sensorsurf2_2_2" pos="0.032 0.0047 0.000" size=".002 .002 .003" type="box" rgba="0.3 0.2 0.1 0.3" euler="0 0 -0.10"/>
                                                            <site name="sensorsurf2_2_3" pos="0.032 0.0047 -0.006" size=".002 .002 .003" type="box" rgba="0.3 0.2 0.1 0.3" euler="0 0 -0.10"/>  
                                                            <site name="sensorsurf2_3_1" pos="0.036 0.004 0.006" size=".002 .002 .003" type="box" rgba="0.3 0.2 0.1 0.3" euler="0 0 -0.20"/>
                                                            <site name="sensorsurf2_3_2" pos="0.036 0.004 0.000" size=".002 .002 .003" type="box" rgba="0.3 0.2 0.1 0.3" euler="0 0 -0.20"/>
                                                            <site name="sensorsurf2_3_3" pos="0.036 0.004 -0.006" size=".002 .002 .003" type="box" rgba="0.3 0.2 0.1 0.3" euler="0 0 -0.20"/>                                                            
                                                            <site name="sensorsurf2_4_1" pos="0.04 0.0035 0.006" size=".002 .002 .003" type="box" rgba="0.3 0.2 0.1 0.3" euler="0 0 -0.20"/>
                                                            <site name="sensorsurf2_4_2" pos="0.04 0.0035 0.000" size=".002 .002 .003" type="box" rgba="0.3 0.2 0.1 0.3" euler="0 0 -0.20"/>
                                                            <site name="sensorsurf2_4_3" pos="0.04 0.0035 -0.006" size=".002 .002 .003" type="box" rgba="0.3 0.2 0.1 0.3" euler="0 0 -0.20"/>
                                                            <site name="sensorsurf2_5_1" pos="0.044 0.0026 0.006" size=".002 .002 .003" type="box" rgba="0.3 0.2 0.1 0.3" euler="0 0 -0.20"/>
                                                            <site name="sensorsurf2_5_2" pos="0.044 0.0026 0.000" size=".002 .002 .003" type="box" rgba="0.3 0.2 0.1 0.3" euler="0 0 -0.20"/>
                                                            <site name="sensorsurf2_5_3" pos="0.044 0.0026 -0.006" size=".002 .002 .003" type="box" rgba="0.3 0.2 0.1 0.3" euler="0 0 -0.20"/>
                                                            <site name="sensorsurf2_6_1" pos="0.048 0.0018 0.006" size=".002 .002 .003" type="box" rgba="0.3 0.2 0.1 0.3" euler="0 0 -0.20"/>
                                                            <site name="sensorsurf2_6_2" pos="0.048 0.0018 0.000" size=".002 .002 .003" type="box" rgba="0.3 0.2 0.1 0.3" euler="0 0 -0.20"/>
                                                            <site name="sensorsurf2_6_3" pos="0.048 0.0018 -0.006" size=".002 .002 .003" type="box" rgba="0.3 0.2 0.1 0.3" euler="0 0 -0.20"/>
                                                            <site name="sensorsurf2_7_1" pos="0.052 0.0000 0.006" size=".002 .002 .003" type="box" rgba="0.3 0.2 0.1 0.3" euler="0 0 -0.20"/>
                                                            <site name="sensorsurf2_7_2" pos="0.052 0.0000 0.000" size=".002 .002 .003" type="box" rgba="0.3 0.2 0.1 0.3" euler="0 0 -0.20"/>
                                                            <site name="sensorsurf2_7_3" pos="0.052 0.0000 -0.006" size=".002 .002 .003" type="box" rgba="0.3 0.2 0.1 0.3" euler="0 0 -0.20"/>
                                                        </body>
                                                    </body>
                                                </body>
                                            </body>
                                    </body>
                                </body>
                            </body>
                        </body>
                    </body>
                </body>
            </body>
        </body>
    <!-- Hinge system -->
    <body pos="0.5 -0.2 0.036" name="Hinge" mocap="true">
        <geom name="surface" type="mesh" rgba="0.3451 0.4431 0.9922 1" mesh="base_link" mass="2"/>
        <inertial pos="0 0 0" quat="1 0 0 0" mass="5.0" diaginertia="0.001 0.001 0.001"/>
        <body name="hinge_link" pos="0.034528 -0.0027781 -0.023241" quat="0 1 0 0" >
            <inertial pos="0.12 0.12 -0.029845" quat="0.924 0 0 0.383" mass="2" diaginertia="0.0001 0.004 0.004" />
            <joint name="hinge_joint" pos="0 0 0" axis="0 0 1" type="hinge" range="-1.39 1.5" springdamper="0.14 0.7" limited="true"/>
            <!--<geom name="rod" pos="0.028636 -0.029552 0.029845" quat="0.509775 0.707102 0.00284346 0.490029" type="mesh" rgba="0.8235 1 0.12 1" mesh="stick_Link" />-->
            <geom name="rod" pos="0.04 0.04 -0.029845" quat="0.653 -0.653 0.271 -0.271" type="mesh" rgba="0.8235 1 0.12 1" mesh="stick_Link" />
            <geom name="rod_holder" pos="0.0 0 0" quat="0 1 0 0" type="mesh" contype="0" rgba="1 0 0.12 1" mesh="hinge_link" conaffinity="0"/>

            <!--Small panel for ur5e-->
            <body name="rod_pen" pos="0.170528 0.2227781 -0.113241" quat="0.924 0 0 -0.383">
                <geom name="rod_pen" pos="0.037 0.06 -0.054845" quat="1 0 0 0" size="0.009 0.042 0.15" type="box" rgba="1 1 0 0.6" contype="8" conaffinity="8"/>
                <inertial pos="0.04 0.1 0" quat="1 0 0 0" mass="5" diaginertia="0.00005 0.0001 0.001"/>

            </body>
            <!--Big pannel for wam robot-->
            <body name="rod_pen_wam" pos="0.070528 0.1227781 -0.113241" quat="0.924 0 0 -0.383">
                <geom name="rod_pen_wam" pos="0.037 0.06 -0.054845" quat="1 0 0 0" size="0.009 0.1 0.15" type="box" rgba="1 1 0 0.6" conaffinity="0"/>
                <inertial pos="0.04 0.1 0" quat="1 0 0 0" mass="3" diaginertia="0.00005 0.0001 0.001"/>
            </body> 
            <!--small blue cube for wam-->
            <body name="flagp_wam" pos="0.14 0.15 -0.25" euler="1.57 -2.396 0">
                <geom name="flagp_wam" pos="0 0 0" quat="1 0 0 0" size="0.03 0.01 0.01" type="box" rgba="0 0 1 1" contype="8" conaffinity="8"/>
            </body>
            <!--small blue cube for ur5e-->
            <body name="flagp" pos="0.24 0.24 -0.28" euler="1.57 -2.396 0">
                <geom name="flagp" pos="0 0 0" quat="1 0 0 0" size="0.03 0.01 0.01" type="box" rgba="0 0 1 1" contype="8" conaffinity="8"/>
            </body>
        </body>
    </body>

    <body name="ur_base" quat="0.707 0 0 -0.707" childclass="ur5e" pos="1.3 0 0">
      <inertial mass="4.0" pos="0 0 0" diaginertia="0.00443333156 0.00443333156 0.0072"/>
      <geom mesh="base_0" material="black" class="visual"/>
      <geom mesh="base_1" material="jointgray" class="visual"/>
      <body name="shoulder_link" pos="0 0 0.163">
        <inertial mass="3.7" pos="0 0 0" diaginertia="0.0102675 0.0102675 0.00666"/>
        <joint name="joint0" class="size3" axis="0 0 1" damping="10" limited="true"/>
        <geom mesh="shoulder_0" material="urblue" class="visual"/>
        <geom mesh="shoulder_1" material="black" class="visual"/>
        <geom mesh="shoulder_2" material="jointgray" class="visual"/>
        <geom class="collision" size="0.06 0.06" pos="0 0 -0.04"/>
        <body name="upper_arm_link" pos="0 0.138 0" quat="1 0 1 0">
          <inertial mass="8.393" pos="0 0 0.2125" diaginertia="0.133886 0.133886 0.0151074"/>
          <joint name="joint1" class="size3" damping="10" limited="true"/>
          <geom mesh="upperarm_0" material="linkgray" class="visual"/>
          <geom mesh="upperarm_1" material="black" class="visual"/>
          <geom mesh="upperarm_2" material="jointgray" class="visual"/>
          <geom mesh="upperarm_3" material="urblue" class="visual"/>
          <geom class="collision" pos="0 -0.04 0" quat="1 1 0 0" size="0.06 0.06"/>
          <geom class="collision" size="0.05 0.2" pos="0 0 0.2"/>
          <body name="forearm_link" pos="0 -0.131 0.425">
            <inertial mass="2.275" pos="0 0 0.196" diaginertia="0.0311796 0.0311796 0.004095"/>
            <joint name="joint2" class="size3_limited" damping="10" limited="true"/>
            <geom mesh="forearm_0" material="urblue" class="visual"/>
            <geom mesh="forearm_1" material="linkgray" class="visual"/>
            <geom mesh="forearm_2" material="black" class="visual"/>
            <geom mesh="forearm_3" material="jointgray" class="visual"/>
            <geom class="collision" pos="0 0.08 0" quat="1 1 0 0" size="0.055 0.06"/>
            <geom class="collision" size="0.038 0.19" pos="0 0 0.2"/>
            <body name="wrist_1_link" pos="0 0 0.392" quat="1 0 1 0">
              <inertial mass="1.219" pos="0 0.127 0" diaginertia="0.0025599 0.0025599 0.0021942"/>
              <joint name="joint3" class="size1" damping="10" limited="true"/>
              <geom mesh="wrist1_0" material="black" class="visual"/>
              <geom mesh="wrist1_1" material="urblue" class="visual"/>
              <geom mesh="wrist1_2" material="jointgray" class="visual"/>
              <geom class="collision" pos="0 0.05 0" quat="1 1 0 0" size="0.04 0.07"/>
              <body name="wrist_2_link" pos="0 0.127 0">
                <inertial mass="1.219" pos="0 0 0.1" diaginertia="0.0025599 0.0025599 0.0021942"/>
                <joint name="joint4" axis="0 0 1" class="size1" damping="10" limited="true"/>
                <geom mesh="wrist2_0" material="black" class="visual"/>
                <geom mesh="wrist2_1" material="urblue" class="visual"/>
                <geom mesh="wrist2_2" material="jointgray" class="visual"/>
                <geom class="collision" size="0.04 0.06" pos="0 0 0.04"/>
                <geom class="collision" pos="0 0.02 0.1" quat="1 1 0 0" size="0.04 0.04"/>
                <body name="wrist_3_link" pos="0 0 0.1">
                  <inertial mass="0.1889" pos="0 0.0771683 0" quat="1 0 0 1"
                    diaginertia="0.000132134 9.90863e-05 9.90863e-05"/>
                  <joint name="joint5" class="size1" damping="10" limited="true"/>
                  <geom material="linkgray" mesh="wrist3" class="visual"/>
                  <geom class="eef_collision" pos="0 0.08 0" quat="1 1 0 0" size="0.04 0.02"/>
                  <site name="attachment_site" pos="0 0.1 0" quat="-1 1 0 0"/>
                  <site name="wrist_UR5_torque_7" pos="0 0.06 0" size="0.05 0.01" type="cylinder" rgba="0 0 0.8 1" euler="1.57 0 0"/>
                  <site name="wrist_UR5_force_7" pos="0 0.06 0" size="0.05 0.01" type="cylinder" rgba="0 0 0.8 1" euler="1.57 0 0"/>    

                  <body name="EE_ur" pos="0 0.17 0" euler="0 0 0"/>
                  
<!--                                     <body name="ur_gripper" pos="0 0.099 0" euler="-1.57 0 1.57">
                                        <site name="eeff" pos="0 0 0.11"/>
                                        <inertial pos="-0.01 0 0" mass="0.001" diaginertia="1.66667e-08 1.66667e-08 1.66667e-08" />
                                            <geom name="light_1" type="sphere" size="0.005" pos="0.035 0 0.0166" material="Light" />
                                            <geom name="light_2" type="sphere" size="0.005" pos="-0.035 0 0.0166" material="Light" />
                                            <geom name="kinova_robotiq_coupler_mesh" type="mesh" mesh="kinova_robotiq_coupler" pos="0 0 0.0466" material="GriMat" />
                                            <geom name="robotiq_85_base_link_mesh" type="mesh" mesh="robotiq_85_base_link" pos="0 0 0.0016" quat="0.707107 0 -0.707107 0" material="GriMat" />
                                            <geom class="x_s_axis"/>
                                            <geom class="y_s_axis"/>
                                            <geom class="z_s_axis"/>
                                            <body name="right_driver" pos="0 -0.0306011 0.054904" quat="0.707107 0 -0.707107 0">
                                                <geom name="right_driver_mesh" type="mesh" mesh="robotiq_85_knuckle_link" material="GriMat" contype="0" conaffinity="0" />
                                                <joint name="right_driver_joint" axis="0 0 1" type="hinge" limited="true" range="0 0.872664626" damping="0.1" solimplimit="0.95 0.99 0.001" solreflimit="0.005 1"/>
                                                <body name="right_coupler" pos="0 -0.0315 0">
                                                    <geom name="right_coupler_mesh" type="mesh" mesh="robotiq_85_finger_link" material="GriMat" contype="0" conaffinity="0" />
                                                    <joint name="right_coupler_joint" axis="0 0 1" type="hinge" limited="true" range="-1.57 0" solimplimit="0.95 0.99 0.001" solreflimit="0.005 1"/>
                                                    <body name="right_follower_link" pos="0.0475 -0.006 0">
                                                        <geom name="right_follower_mesh" pos="0.0025 0.021 0" type="mesh" mesh="robotiq_85_finger_tip_link" material="GriMat" />
                                                        <inertial pos="0.022825 0.0050491 0.0004203" quat="0.508412 0.51165 0.489583 0.489939" mass="0.041377" diaginertia="3.2434e-005 1.22753e-005 3.09987e-006" />
                                                        <site name="touch_right" type="box" pos="0.027 0.029 0" size=".0002 .01 .017" rgba="1 0 0 1" euler="1.57 1.57 0" group="2"/>
                                                        <site name="tip_right" type="box" pos="0.027 0.028 0" size="0.002 0.01 0.017" rgba="0 1 0 1" euler="1.57 1.57 0" group="4"/>
                                                        <joint name="right_follower_joint" axis="0 0 1" type="hinge" limited="true" range="-0.872664 0.872664" solimplimit="0.95 0.99 0.001" solreflimit="0.005 1"/>
                                                    </body>
                                                </body>
                                            </body>

                                            <body name="right_spring_link" pos="0.0016 -0.012 0.0614" quat="0.707107 0 -0.707107 0">
                                                <geom name="right_spring_mesh" type="mesh" pos="0 -0.0005 0.0016" mesh="robotiq_85_inner_knuckle_link" material="GriMat" contype="0" conaffinity="0" />
                                                <joint name="right_spring_joint" axis="0 0 1" type="hinge" limited="true" range="0 1" stiffness="0.5" springref="2.62" damping="0.00125"/>
                                            </body>


                                            <body name="left_driver" pos="0 0.0306011 0.054904" quat="0 0.707107 0 0.707107">
                                                <geom name="left_driver_mesh" type="mesh" mesh="robotiq_85_knuckle_link" material="GriMat" contype="0" conaffinity="0" />
                                                <joint name="left_driver_joint" axis="0 0 1" type="hinge" limited="true" range="0 0.872664626" armature="0.5" damping="0.1" solimplimit="0.95 0.99 0.001" solreflimit="0.005 1"/>
                                                <body name="left_coupler" pos="0 -0.0315 0">
                                                    <geom name="left_coupler_mesh" type="mesh" mesh="robotiq_85_finger_link" material="GriMat" contype="0" conaffinity="0" />
                                                    <joint name="left_coupler_joint" axis="0 0 1" type="hinge" limited="true" range="-1.57 0" solimplimit="0.95 0.99 0.001" solreflimit="0.005 1"/>
                                                    <body name="left_follower_link" pos="0.0475 -0.006 0">
                                                        <geom name="left_follower_mesh" pos="0.0025 0.021 0" type="mesh" mesh="robotiq_85_finger_tip_link" material="GriMat" />
                                       surface                 <inertial pos="0.022825 0.0050491 0.0004203" quat="0.508412 0.51165 0.489583 0.489939" mass="0.041377" diaginertia="3.2434e-005 1.22753e-005 3.09987e-006" />
                                                        <site name="touch_left" type="box" pos="0.027 0.029 0" size=".0002 .01 .017" rgba="1 0 0 0.3" euler="1.57 1.57 0" group="2"/>
                                                        <site name="tip_left" type="box" pos="0.027 0.028 0" size=".002 .01 .017" rgba="1 0 0 0.3" euler="1.57 1.57 0" group="4"/>
                                                        <joint name="left_follower_joint" axis="0 0 1" type="hinge" limited="true" range="-0.872664 0.872664" solimplimit="0.95 0.99 0.001" solreflimit="0.005 1"/>
                                                    </body>
                                                </body>

                                            </body>

                                            <body name="left_spring_link" pos="0.0016 0.012 0.0614" quat="0 0.707107 0 0.707107">
                                                <geom name="left_spring_mesh" type="mesh" pos="0 0.0005 0.0016" mesh="robotiq_85_inner_knuckle_link" material="GriMat" contype="0" conaffinity="0" />
                                                <joint name="left_spring_joint" axis="0 0 1" type="hinge" limited="true" range="0 1" stiffness="0.5" springref="2.62" damping="0.00125"/>
                                            </body>
                                    </body> -->
                                    <body name="base_mount" pos="0 0.099 0.00" childclass="2f85" euler="-1.57 0 0">
                                      <geom class="vis85" mesh="85_base_mount" material="black"/>
                                      <geom class="col85" mesh="85_base_mount"/>
                                      <body name="base" pos="0 0 0.0038" quat="1 0 0 -1">
                                        <inertial mass="0.777441" pos="0 -2.70394e-05 0.0354675" quat="1 -0.00152849 0 0"
                                          diaginertia="0.000260285 0.000225381 0.000152708"/>
                                        <geom class="vis85" mesh="85_base" material="black"/>
                                        <geom class="col85" mesh="85_base"/>
                                        <site name="pinch" pos="0 0 0.145" type="sphere" group="5" rgba="0.9 0.9 0.9 1" size="0.005"/>
                                        <!-- Right-hand side 4-bar linkage -->
                                        <body name="right_driver_85" pos="0 0.0306011 0.054904">
                                          <inertial mass="0.00899563" pos="2.96931e-12 0.0177547 0.00107314" quat="0.681301 0.732003 0 0"
                                            diaginertia="1.72352e-06 1.60906e-06 3.22006e-07"/>
                                          <joint name="right_driver_joint_85" class="driver"/>
                                          <geom class="vis85" mesh="85_driver" material="gray"/>
                                          <geom class="col85" mesh="85_driver"/>
                                          <body name="right_coupler_85" pos="0 0.0315 -0.0041">
                                            <inertial mass="0.0140974" pos="0 0.00301209 0.0232175" quat="0.705636 -0.0455904 0.0455904 0.705636"
                                              diaginertia="4.16206e-06 3.52216e-06 8.88131e-07"/>
                                            <joint name="right_coupler_joint_85" class="coupler"/>
                                            <geom class="vis85" mesh="85_coupler" material="black"/>
                                            <geom class="col85" mesh="85_coupler"/>
                                          </body>
                                        </body>
                                        <body name="right_spring_link_85" pos="0 0.0132 0.0609">
                                          <inertial mass="0.0221642" pos="-8.65005e-09 0.0181624 0.0212658" quat="0.663403 -0.244737 0.244737 0.663403"
                                            diaginertia="8.96853e-06 6.71733e-06 2.63931e-06"/>
                                          <joint name="right_spring_link_joint" class="spring_link"/>
                                          <geom class="vis85" mesh="85_spring_link" material="black"/>
                                          <geom class="col85" mesh="85_spring_link"/>
                                          <body name="right_follower_85" pos="0 0.055 0.0375">
                                            <inertial mass="0.0125222" pos="0 -0.011046 0.0124786" quat="1 0.1664 0 0"
                                              diaginertia="2.67415e-06 2.4559e-06 6.02031e-07"/>
                                            <joint name="right_follower_joint_85" class="follower"/>
                                            <geom class="vis85" mesh="85_follower" material="black"/>
                                            <geom class="col85" mesh="85_follower"/>
                                            <body name="right_pad" pos="0 -0.0189 0.01352">
                                              <geom class="pad_box1" name="right_pad1"/>
                                              <geom class="pad_box2" name="right_pad2"/>
                                              <site name="touch_right" type="box" pos="0 -0.007 0.02" size=".0002 .01 .017" rgba="1 0 0 0.3" euler="0 0 1.57" group="2"/>
                                              <inertial mass="0.0035" pos="0 -0.0025 0.0185" quat="0.707107 0 0 0.707107"
                                                diaginertia="4.73958e-07 3.64583e-07 1.23958e-07"/>
                                              <geom class="vis85" mesh="85_pad"/>
                                              <body name="right_silicone_pad">
                                                <geom class="vis85" mesh="85_silicone_pad" material="black"/>
                                              </body>
                                            </body>
                                          </body>
                                        </body>
                                        <!-- Left-hand side 4-bar linkage -->
                                        <body name="left_driver_85" pos="0 -0.0306011 0.054904" quat="0 0 0 1">
                                          <inertial mass="0.00899563" pos="0 0.0177547 0.00107314" quat="0.681301 0.732003 0 0"
                                            diaginertia="1.72352e-06 1.60906e-06 3.22006e-07"/>
                                          <joint name="left_driver_joint_85" class="driver"/>
                                          <geom class="vis85" mesh="85_driver" material="gray"/>
                                          <geom class="col85" mesh="85_driver"/>
                                          <body name="left_coupler_85" pos="0 0.0315 -0.0041">
                                            <inertial mass="0.0140974" pos="0 0.00301209 0.0232175" quat="0.705636 -0.0455904 0.0455904 0.705636"
                                              diaginertia="4.16206e-06 3.52216e-06 8.88131e-07"/>
                                            <joint name="left_coupler_joint_85" class="coupler"/>
                                            <geom class="vis85" mesh="85_coupler" material="black"/>
                                            <geom class="col85" mesh="85_coupler"/>
                                          </body>
                                        </body>
                                        <body name="left_spring_link_85" pos="0 -0.0132 0.0609" quat="0 0 0 1">
                                          <inertial mass="0.0221642" pos="-8.65005e-09 0.0181624 0.0212658" quat="0.663403 -0.244737 0.244737 0.663403"
                                            diaginertia="8.96853e-06 6.71733e-06 2.63931e-06"/>
                                          <joint name="left_spring_link_joint_85" class="spring_link"/>
                                          <geom class="vis85" mesh="85_spring_link" material="black"/>
                                          <geom class="col85" mesh="85_spring_link"/>
                                          <body name="left_follower_85" pos="0 0.055 0.0375">
                                            <inertial mass="0.0125222" pos="0 -0.011046 0.0124786" quat="1 0.1664 0 0"
                                              diaginertia="2.67415e-06 2.4559e-06 6.02031e-07"/>
                                            <joint name="left_follower_joint_85" class="follower"/>
                                            <geom class="vis85" mesh="85_follower" material="black"/>
                                            <geom class="col85" mesh="85_follower"/>
                                            <body name="left_pad" pos="0 -0.0189 0.01352">
                                              <geom class="pad_box1" name="left_pad1"/>
                                              <geom class="pad_box2" name="left_pad2"/>
                                              <site name="touch_left" type="box" pos="0 -0.007 0.02" size=".0002 .01 .017" rgba="1 0 0 0.3" euler="0 0 1.57" group="2"/>
                                              <inertial mass="0.0035" pos="0 -0.0025 0.0185" quat="1 0 0 1"
                                                diaginertia="4.73958e-07 3.64583e-07 1.23958e-07"/>
                                              <geom class="vis85" mesh="85_pad"/>
                                              <body name="left_silicone_pad">
                                                <geom class="vis85" mesh="85_silicone_pad" material="black"/>
                                              </body>
                                            </body>
                                          </body>
                                        </body>
                                      </body>
                                    </body>
                
                </body>
              </body>
            </body>
          </body>
        </body>
      </body>
    </body>
    </worldbody>

  <contact>
<!--     <exclude body1="ur_gripper" body2="left_driver"/>
    <exclude body1="ur_gripper" body2="right_driver"/>
    <exclude body1="ur_gripper" body2="left_spring_link"/>
    <exclude body1="ur_gripper" body2="right_spring_link"/>
    <exclude body1="right_spring_link" body2="right_follower_link"/>
    <exclude body1="left_spring_link" body2="left_follower_link"/> -->
    <exclude body1="base" body2="left_driver_85"/>
    <exclude body1="base" body2="right_driver_85"/>
    <exclude body1="base" body2="left_spring_link_85"/>
    <exclude body1="base" body2="right_spring_link_85"/>
    <exclude body1="right_coupler_85" body2="right_follower_85"/>
    <exclude body1="left_coupler_85" body2="left_follower_85"/>
    <pair name="isotropic" geom1="surface" geom2="rod" condim="3" friction="0.3 1"/>
  </contact>

  <tendon>
<!--     <fixed name="split">
      <joint joint="right_driver_joint" coef="0.5"/>
      <joint joint="left_driver_joint" coef="0.5"/>
    </fixed> -->
    <fixed name="split_85">
      <joint joint="right_driver_joint_85" coef="0.5"/>
      <joint joint="left_driver_joint_85" coef="0.5"/>
    </fixed>
  </tendon>

  <equality>
<!--     <connect anchor="0.0184 0.015 0" body1="right_follower_link" body2="right_spring_link" solimp="0.95 0.99 0.001"
        solref="0.001 1"/>
    <connect anchor="0.0184 0.015 0" body1="left_follower_link" body2="left_spring_link" solimp="0.95 0.99 0.001"
        solref="0.001 1"/>
    <joint joint1="right_driver_joint" joint2="left_driver_joint" polycoef="0 1 0 0 0"
        solimp="0.95 0.99 0.001" solref="0.00511"/> -->
    <connect anchor="0 0 0" body1="right_follower_85" body2="right_coupler_85" solimp="0.95 0.99 0.001" solref="0.005 1"/>
    <connect anchor="0 0 0" body1="left_follower_85" body2="left_coupler_85" solimp="0.95 0.99 0.001" solref="0.005 1"/>
    <joint joint1="right_driver_joint_85" joint2="left_driver_joint_85" polycoef="0 1 0 0 0" solimp="0.95 0.99 0.001"
      solref="0.005 1"/>
  </equality>


    <actuator>
        <motor name="joint0_motor" joint="wam/joints/base_yaw"/>
        <motor name="joint1_motor" joint="wam/joints/shoulder_pitch_joint"/>
        <motor name="joint2_motor" joint="wam/joints/shoulder_yaw"/>
        <motor name="joint3_motor" joint="wam/joints/elbow_pitch"/>
        <motor name="joint4_motor" joint="wam/joints/wrist_yaw"/>
        <motor name="joint5_motor" joint="wam/joints/wrist_pitch"/>
        <motor name="joint6_motor" joint="wam/joints/palm_yaw"/>
<!--         <general biastype="affine" name="actuator8" tendon="split" forcelimited="true" forcerange="-5 5"
        ctrllimited="true" ctrlrange="0 255" gainprm="0.3137255 0 0" biasprm="0 -100 -10"/>
 -->    
        <general class="2f85" name="actuator8" tendon="split_85" forcerange="-5 5" ctrlrange="0 255"
        gainprm="0.3137255 0 0" biasprm="0 -100 -10"/>  
        <general class="size3" name="shoulder_pan" joint="joint0" forcelimited="true" forcerange="-5 5" ctrllimited="true"/>
        <general class="size3" name="shoulder_lift" joint="joint1" forcelimited="true" forcerange="-5 5" ctrllimited="true"/>
        <general class="size3_limited" name="elbow" joint="joint2" forcelimited="true" forcerange="-5 5" ctrllimited="true"/>
        <general class="size1" name="wrist_1" joint="joint3" forcelimited="true" forcerange="-5 5" ctrllimited="true"/>
        <general class="size1" name="wrist_2" joint="joint4" forcelimited="true" forcerange="-5 5" ctrllimited="true"/>
        <general class="size1" name="wrist_3" joint="joint5" forcelimited="true" forcerange="-5 5" ctrllimited="true"/>
        <motor name="hinge_act_test" joint="hinge_joint"/>
    </actuator>

    <sensor>
        <touch name="fsensor3_0_1" site="sensorsurf3_0_1" />
        <touch name="fsensor3_0_2" site="sensorsurf3_0_2" />
        <touch name="fsensor3_0_3" site="sensorsurf3_0_3" />
        <touch name="fsensor3_1_1" site="sensorsurf3_1_1" />
        <touch name="fsensor3_1_2" site="sensorsurf3_1_2" />
        <touch name="fsensor3_1_3" site="sensorsurf3_1_3" />
        <touch name="fsensor3_2_1" site="sensorsurf3_2_1" />
        <touch name="fsensor3_2_2" site="sensorsurf3_2_3" />
        <touch name="fsensor3_2_3" site="sensorsurf3_2_3" />
        <touch name="fsensor3_3_1" site="sensorsurf3_3_1" />
        <touch name="fsensor3_3_2" site="sensorsurf3_3_2" />
        <touch name="fsensor3_3_3" site="sensorsurf3_3_3" />
        <touch name="fsensor3_4_1" site="sensorsurf3_4_1" />
        <touch name="fsensor3_4_2" site="sensorsurf3_4_2" />
        <touch name="fsensor3_4_3" site="sensorsurf3_4_3" />
        <touch name="fsensor3_5_1" site="sensorsurf3_5_1" />
        <touch name="fsensor3_5_2" site="sensorsurf3_5_3" />
        <touch name="fsensor3_5_3" site="sensorsurf3_5_3" /> 
        <touch name="fsensor3_6_1" site="sensorsurf3_6_1" />
        <touch name="fsensor3_6_2" site="sensorsurf3_6_2" />
        <touch name="fsensor3_6_3" site="sensorsurf3_6_3" />
        <touch name="fsensor3_7_1" site="sensorsurf3_7_1" />
        <touch name="fsensor3_7_2" site="sensorsurf3_7_2" />
        <touch name="fsensor3_7_3" site="sensorsurf3_7_3" />
        <touch name="ur_touch_right" site="touch_right" />
        <touch name="ur_touch_left" site="touch_left" /> 

        <!--Define 6-axis Torque/Force sensor for WAM-->
        <torque name="wrist_WAM_torque" site="wrist_WAM_torque_7" />
        <force name="wrist_WAM_force" site="wrist_WAM_force_7"/>

        <torque name="wrist_UR5_torque" site="wrist_UR5_torque_7" />
        <force name="wrist_UR5_force" site="wrist_UR5_force_7"/>

        <velocimeter name="xvelp" site="speed_sensor"/>
        <gyro name="xvelr" site="speed_sensor"/>


    </sensor>

</mujoco>
